Workbook

Sheet Total Recap Hours
A3: Employee # | B3: Employee Name | C3: STATUS | D3: Position | E3: Social Security | F3: Address Line 1 + Address Line 2 | G3: City, State Zip Code (Formatted) | H3: Phone Number | I3: DOB | J3: DOH | K3: Hours | L3: Total
A4: 100029581 | B4: Acosta, Vilma E. | C4: Active | D4: Dishwasher | E4: 710-94-5604 | F4: 153 w 71 st | G4: Los Angeles, CA 90003 | H4: (213) 446-4417 | I4: 26170 | J4: 43182 | K4: =SUMIF(Data!$C$6:$V$29146,A4,Data!$V$6:$V$29146) -> 96.84 | L4: =IFERROR(K4*0.25,"") -> 24.21
A5: 100090935 | B5: Adamashvili, Nik | C5: Active | D5: Lead Bartender, Concess | E5: 292-99-5284 | F5: 15136 Magnolia Blvd | G5: Sherman Oaks, CA 91403 | H5: (213) 335-0335 | I5: 34974 | J5: 45736 | K5: =SUMIF(Data!$C$6:$V$29146,A5,Data!$V$6:$V$29146) -> 0 | L5: =IFERROR(K5*0.25,"") -> 0
A6: 100082265 | B6: Addison, Richard | C6: Active | D6: Concession Stand Worker | E6: 610-59-5928 | F6: 5153 S Victoria Ave | G6: Los Angeles, CA 90043 | H6: (213) 820-2054 | I6: 30930 | J6: 45414 | K6: =SUMIF(Data!$C$6:$V$29146,A6,Data!$V$6:$V$29146) -> 0 | L6: =IFERROR(K6*0.25,"") -> 0
A7: 100089151 | B7: Adkins Sr., Christopher M. | C7: Active | D7: Club Attendant | E7: 612-92-8587 | F7: 2440 East 112thplace | G7: Los Angeles, CA 90059 | H7: (213) 779-8809 | I7: 35316 | J7: 45688 | K7: =SUMIF(Data!$C$6:$V$29146,A7,Data!$V$6:$V$29146) -> 0 | L7: =IFERROR(K7*0.25,"") -> 0
A8: 100087239 | B8: Aguilar, Caesar | C8: Active | D8: Lead Bartender, Concess | E8: 616-84-1189 | F8: 6929 Coldwater Canyon Ave Apt 107 | G8: North Hollywood, CA 91605 | H8: (818) 599-4140 | I8: 34964 | J8: 45546 | K8: =SUMIF(Data!$C$6:$V$29146,A8,Data!$V$6:$V$29146) -> 0 | L8: =IFERROR(K8*0.25,"") -> 0
A9: 100082259 | B9: Aguilera, Kevin | C9: Active | D9: Dishwasher | E9: 608-80-8895 | F9: 9706 San Miguel Ave | G9: South Gate, CA 90280 | H9: (323) 775-3036 | I9: 33551 | J9: 45414 | K9: =SUMIF(Data!$C$6:$V$29146,A9,Data!$V$6:$V$29146) -> 0 | L9: =IFERROR(K9*0.25,"") -> 0
A10: 100087281 | B10: AGUILERA, MARCOS | C10: Active | D10: Cook 3 | E10: 605-90-0984 | F10: 450 s Normandie Ave Apt 109 | G10: Los Angeles, CA 90020 | H10: (323) 500-3392 | I10: 34967 | J10: 45546 | K10: =SUMIF(Data!$C$6:$V$29146,A10,Data!$V$6:$V$29146) -> 0 | L10: =IFERROR(K10*0.25,"") -> 0
A11: 100004749 | B11: Aguirre, Harold W. | C11: Active | D11: Lead Bartender, Concess | E11: 604-60-9937 | F11: 613 W Wardlow Rd | G11: Long Beach, CA 90806 | H11: (562) 761-4202 | I11: 28294 | J11: 45688 | K11: =SUMIF(Data!$C$6:$V$29146,A11,Data!$V$6:$V$29146) -> 0 | L11: =IFERROR(K11*0.25,"") -> 0
A12: 100062550 | B12: Albitre, Randy | C12: Active | D12: Concession Stand Worker | E12: 558-67-5709 | F12: 526 E.6th St. Unit 304 | G12: Los Angeles, CA 90021 | H12: (323) 571-0693 | I12: 29757 | J12: 44832 | K12: =SUMIF(Data!$C$6:$V$29146,A12,Data!$V$6:$V$29146) -> 0 | L12: =IFERROR(K12*0.25,"") -> 0
A13: 100064555 | B13: ALCAZAR, LOUIE A. | C13: Active | D13: Concession Stand Worker | E13: 624-11-2408 | F13: 4172 wall st | G13: Los Angeles, CA 90011 | H13: (323) 812-8635 | I13: 36222 | J13: 44958 | K13: =SUMIF(Data!$C$6:$V$29146,A13,Data!$V$6:$V$29146) -> 0 | L13: =IFERROR(K13*0.25,"") -> 0
A14: 100093400 | B14: Aleman, Amelia | C14: Active | D14: Cook 3 | E14: 623-44-4835 | F14: 12223 Atlantic Ave Unit 1305 | G14: Lynwood, CA 90262 | H14: (323) 273-7429 | I14: 26200 | J14: 45785 | K14: =SUMIF(Data!$C$6:$V$29146,A14,Data!$V$6:$V$29146) -> 0 | L14: =IFERROR(K14*0.25,"") -> 0
A15: 100094450 | B15: Aleman, Fransico | C15: Active | D15: Dishwasher | E15: 613-17-1565 | F15: 435 e 105th st | G15: Los angeles, CA 90003 | H15: (323) 994-7216 | I15: 36436 | J15: 45805 | K15: =SUMIF(Data!$C$6:$V$29146,A15,Data!$V$6:$V$29146) -> 0 | L15: =IFERROR(K15*0.25,"") -> 0
A16: 100087249 | B16: Allen, Yeshayahuw | C16: Active | D16: Cashier, Concessions | E16: 606-35-4445 | F16: 1947 W 39th Pl Van Ness Avenue | G16: Los Angeles, CA 90062 | H16: (323) 217-8663 | I16: 37460 | J16: 45546 | K16: =SUMIF(Data!$C$6:$V$29146,A16,Data!$V$6:$V$29146) -> 0 | L16: =IFERROR(K16*0.25,"") -> 0
A17: 100071939 | B17: Alonso, Jose | C17: Active | D17: Cook 3 | E17: 626-47-1926 | F17: 514 S Westlake Ave, Apt 107 | G17: Los Angeles, CA 90057 | H17: (213) 705-9380 | I17: 38282 | J17: 45112 | K17: =SUMIF(Data!$C$6:$V$29146,A17,Data!$V$6:$V$29146) -> 0 | L17: =IFERROR(K17*0.25,"") -> 0
A18: 100087236 | B18: ALVARADO, FREDY | C18: Active | D18: Cook 3 | E18: 626-55-1785 | F18: 5334 Oakland St | G18: Los Angeles, CA 90032 | H18: (323) 714-7509 | I18: 38767 | J18: 45546 | K18: =SUMIF(Data!$C$6:$V$29146,A18,Data!$V$6:$V$29146) -> 0 | L18: =IFERROR(K18*0.25,"") -> 0
A19: 100029801 | B19: Alvarado, Leticia | C19: Active | D19: Bartender, Premium | E19: 553-33-8803 | F19: 10855 Terra Vista Pkwy Apt 126 | G19: Rancho Cucamonga, CA 91730 | H19: (626) 260-2506 | I19: 25507 | J19: 43182 | K19: =SUMIF(Data!$C$6:$V$29146,A19,Data!$V$6:$V$29146) -> 6.67 | L19: =IFERROR(K19*0.25,"") -> 1.6675
A20: 100087241 | B20: ALVAREZ, LUIS F. | C20: Active | D20: Cashier, Concessions | E20: 608-59-1294 | F20: 629 w 43rd st | G20: Los angeles, CA 90037 | H20: (424) 404-2342 | I20: 38925 | J20: 45546 | K20: =SUMIF(Data!$C$6:$V$29146,A20,Data!$V$6:$V$29146) -> 0 | L20: =IFERROR(K20*0.25,"") -> 0
A21: 100093373 | B21: Ambrocio IV, Marco A. | C21: Active | D21: Concession Stand Worker | E21: 625-59-6704 | F21: 15348 Firmona Ave | G21: Lawndale, CA 90260 | H21: (310) 706-8049 | I21: 39009 | J21: 45785 | K21: =SUMIF(Data!$C$6:$V$29146,A21,Data!$V$6:$V$29146) -> 0 | L21: =IFERROR(K21*0.25,"") -> 0
A22: 100084221 | B22: Amigon, Judith | C22: Active | D22: Dishwasher | E22: 623-78-6472 | F22: 181 W 41st Pl Apt, 5 | G22: Los Anfgeles, CA 90037 | H22: (626) 549-7403 | I22: 25421 | J22: 45456 | K22: =SUMIF(Data!$C$6:$V$29146,A22,Data!$V$6:$V$29146) -> 0 | L22: =IFERROR(K22*0.25,"") -> 0
A23: 100089112 | B23: Anderson, Rashad | C23: Active | D23: Club Attendant | E23: 591-11-4797 | F23: 888 S Olive St Apt 3007 | G23: Los Angeles, CA 90014 | H23: (813) 796-2072 | I23: 33318 | J23: 45688 | K23: =SUMIF(Data!$C$6:$V$29146,A23,Data!$V$6:$V$29146) -> 0 | L23: =IFERROR(K23*0.25,"") -> 0
A24: 100074386 | B24: ANDON Gomez, KEVIN D. | C24: Active | D24: Runner, Suites | E24: 096-88-6401 | F24: 5914 Willowcrest Apt 1 | G24: North Hollywood, CA 91601 | H24: (818) 209-5759 | I24: 34813 | J24: 45189 | K24: =SUMIF(Data!$C$6:$V$29146,A24,Data!$V$6:$V$29146) -> 0 | L24: =IFERROR(K24*0.25,"") -> 0
A25: 100093414 | B25: Apolinar, Carlos | C25: Active | D25: Cashier, Concessions | E25: 611-31-2369 | F25: 133 E 25th St | G25: Los Angeles, CA 90011 | H25: (323) 816-5696 | I25: 37222 | J25: 45785 | K25: =SUMIF(Data!$C$6:$V$29146,A25,Data!$V$6:$V$29146) -> 0 | L25: =IFERROR(K25*0.25,"") -> 0
A26: 100082257 | B26: Apolinar, Citlali | C26: Active | D26: Concession Stand Worker | E26: 624-45-2335 | F26: 133 E 25th St | G26: Los Angeles, CA 90011 | H26: (323) 379-9899 | I26: 38147 | J26: 45414 | K26: =SUMIF(Data!$C$6:$V$29146,A26,Data!$V$6:$V$29146) -> 0 | L26: =IFERROR(K26*0.25,"") -> 0
A27: 100029855 | B27: Aquino Carrillo, Febronia J. | C27: Active | D27: Dishwasher | E27: 780-86-0496 | F27: 466 W 50TH ST | G27: Los Angeles, CA 90037 | H27: (213) 260-5668 | I27: 24649 | J27: 43182 | K27: =SUMIF(Data!$C$6:$V$29146,A27,Data!$V$6:$V$29146) -> 20.35 | L27: =IFERROR(K27*0.25,"") -> 5.0875
A28: 100084258 | B28: Arellanes, Jacob | C28: Active | D28: Concession Stand Worker | E28: 614-80-4086 | F28: 762 Via Altamira Apt 21 | G28: Montebello, CA 90640 | H28: (323) 712-5623 | I28: 31246 | J28: 45456 | K28: =SUMIF(Data!$C$6:$V$29146,A28,Data!$V$6:$V$29146) -> 0 | L28: =IFERROR(K28*0.25,"") -> 0
A29: 100089129 | B29: Arredondo, Militza | C29: Active | D29: Dishwasher | E29: 062-17-7339 | F29: 1780 E 109th Pl | G29: Los Angeles, CA 90059 | H29: (323) 635-4727 | I29: 34572 | J29: 45688 | K29: =SUMIF(Data!$C$6:$V$29146,A29,Data!$V$6:$V$29146) -> 0 | L29: =IFERROR(K29*0.25,"") -> 0
A30: 100087283 | B30: Arteaga, Juan A. | C30: Active | D30: Runner, Suites | E30: 621-78-4344 | F30: 10603 Felton ave | G30: Lennox, CA 90304 | H30: (213) 844-1561 | I30: 34452 | J30: 45546 | K30: =SUMIF(Data!$C$6:$V$29146,A30,Data!$V$6:$V$29146) -> 0 | L30: =IFERROR(K30*0.25,"") -> 0
A31: 100059503 | B31: ARTIGA, RODOLFO | C31: Active | D31: Dishwasher | E31: 624-46-5343 | F31: 429 S.Rampart blvd apt2 | G31: los angeles, CA 90057 | H31: (213) 247-4463 | I31: 21292 | J31: 44735 | K31: =SUMIF(Data!$C$6:$V$29146,A31,Data!$V$6:$V$29146) -> 0 | L31: =IFERROR(K31*0.25,"") -> 0
A32: 100040078 | B32: ATKINS, SASHA | C32: Active | D32: Suite Attendant | E32: 608-28-2754 | F32: 4575 Ramona Ave 1 | G32: La Verne, CA 91750 | H32: (562) 205-7829 | I32: 32666 | J32: 43628 | K32: =SUMIF(Data!$C$6:$V$29146,A32,Data!$V$6:$V$29146) -> 0 | L32: =IFERROR(K32*0.25,"") -> 0
A33: 100089134 | B33: Avalos, Gabriela C. | C33: Active | D33: Dishwasher | E33: 833-07-5886 | F33: 10413 S Gravillea Ave | G33: Inglewood, CA 90304 | H33: (424) 393-8674 | I33: 23427 | J33: 45688 | K33: =SUMIF(Data!$C$6:$V$29146,A33,Data!$V$6:$V$29146) -> 0 | L33: =IFERROR(K33*0.25,"") -> 0
A34: 100093395 | B34: Avelar, Yovani | C34: Active | D34: Cashier, Concessions | E34: 624-98-2754 | F34: 1599 E 45th st Apt 3 | G34: Los Angeles, CA 90011 | I34: 35308 | J34: 45785 | K34: =SUMIF(Data!$C$6:$V$29146,A34,Data!$V$6:$V$29146) -> 0 | L34: =IFERROR(K34*0.25,"") -> 0
A35: 100093374 | B35: Avila, Francisco | C35: Active | D35: Cashier, Concessions | E35: 612-55-7694 | F35: 11507 S New Hampshire Ave | G35: Los Angeles, CA 90044 | H35: (323) 326-2496 | I35: 38704 | J35: 45785 | K35: =SUMIF(Data!$C$6:$V$29146,A35,Data!$V$6:$V$29146) -> 0 | L35: =IFERROR(K35*0.25,"") -> 0
A36: 100087267 | B36: Bachez, Elba | C36: Active | D36: Dishwasher | E36: 085-87-9317 | F36: 2222 S FIGUEROA ST PH25 | G36: LOS ANGELES, CA 90007 | H36: (323) 789-9181 | I36: 23735 | J36: 45546 | K36: =SUMIF(Data!$C$6:$V$29146,A36,Data!$V$6:$V$29146) -> 0 | L36: =IFERROR(K36*0.25,"") -> 0
A37: 100084254 | B37: Bailon, Denisse M. | C37: Active | D37: Cook 2 | E37: 729-14-9013 | F37: 1514 West 46 Street 1/2 | G37: Los Angeles, CA 90062 | H37: (323) 694-8834 | I37: 32599 | J37: 45456 | K37: =SUMIF(Data!$C$6:$V$29146,A37,Data!$V$6:$V$29146) -> 0 | L37: =IFERROR(K37*0.25,"") -> 0
A38: 100013984 | B38: Bailon, Maria | C38: Active | D38: Lead Bartender, Concess | E38: 551-99-3124 | F38: 3951 HALLDALE AVE. | G38: Los Angeles, CA 90062 | H38: (213) 220-0714 | I38: 24353 | J38: 42270 | K38: =SUMIF(Data!$C$6:$V$29146,A38,Data!$V$6:$V$29146) -> 0 | L38: =IFERROR(K38*0.25,"") -> 0
A39: 100084236 | B39: Baker, Aniyah | C39: Active | D39: Cashier, Concessions | E39: 760-01-7557 | F39: 1205 W 65th Pl | G39: Los Angeles, CA 90044 | H39: (539) 281-9291 | I39: 38645 | J39: 45456 | K39: =SUMIF(Data!$C$6:$V$29146,A39,Data!$V$6:$V$29146) -> 0 | L39: =IFERROR(K39*0.25,"") -> 0
A40: 100037610 | B40: BAKER, TYNASIA L. | C40: Active | D40: Concessions Stand Lead | E40: 610-84-2914 | F40: 3016 w 82nd Street | G40: Inglewood, CA 90305 | H40: (323) 674-4900 | I40: 34934 | J40: 45546 | K40: =SUMIF(Data!$C$6:$V$29146,A40,Data!$V$6:$V$29146) -> 0 | L40: =IFERROR(K40*0.25,"") -> 0
A41: 100064799 | B41: BALBUENA, YOLANDA | C41: Active | D41: Cook 2 | E41: 353-65-4445 | F41: 4212 s. Grand ave | G41: LOS ANGELES, CA 90037 | H41: (323) 697-1187 | I41: 26972 | J41: 44965 | K41: =SUMIF(Data!$C$6:$V$29146,A41,Data!$V$6:$V$29146) -> 0 | L41: =IFERROR(K41*0.25,"") -> 0
A42: 100082245 | B42: Barnes, Darrionna | C42: Active | D42: In-Seat Server | E42: 346-90-4314 | F42: 752 S Main St 452 | G42: Los Angeles, CA 90014 | H42: (773) 541-0977 | I42: 34635 | J42: 45414 | K42: =SUMIF(Data!$C$6:$V$29146,A42,Data!$V$6:$V$29146) -> 0 | L42: =IFERROR(K42*0.25,"") -> 0
...

Sheet Data
A1: PERSON TIME HISTORY REPORT by Working Dept
A2: 12/01/2025 Thru 01/05/2026
A3: Employee Type(s): FPVST
A5: Person Department | B5: Working Dept | C5: Person id | D5: Person Name | E5: PersonType | F5: EventID | G5: Event Name | H5: Event Start | I5: Facility | J5: Position | K5: PositionID | L5: Pos.Team | M5: Location | N5: Date | O5: Day of Week | P5: Weekend Event | Q5: IN Time | R5: OUT Time | S5: Rate | T5: RateType | U5: PayType | V5: Total Hrs | W5: Reg Hrs | X5: OT Hrs | Y5: DT Hrs | Z5: Other Hrs | AA5: Missed Meal Hrs | AB5: Missed Rest Hrs | AC5: Addl Event Pay | AD5: Commission | AE5: Tips | AF5: Tips CashedOut | AG5: Svc/Admin Chg | AH5: Reg Earnings | AI5: OT Earnings | AJ5: DT Earnings | AK5: Other Earnings | AL5: Missed Meal Earnings | AM5: Missed Rest Earnings | AN5: Allowances | AO5: Deductions | AP5: Total Earnings | AQ5: Is Late | AR5: Actual IN | AS5: Actual OUT | AT5: Sched IN | AU5: Sched OUT | AV5: Person Team/Area | AW5: HomeComponent | AX5: WkgComponent | AY5: Meal Hrs | AZ5: Meal Times | BA5: Approved Date | BB5: Flat Rate Reduction | BC5: Dress Allowance Hrs | BD5: WorkType_ID | BE5: WorkType Desc. | BF5: Comments | BG5: Event Additional Pay Hours 1 | BH5: Event Additional Pay Hours 2 | BI5: Special Handling Type | BJ5: Hours for Additional Pay Rules
A6: FCADM | B6: FCADM | C6: 100019803 | D6: ROBERTS, PAMALA B | E6: PT | F6: FDAILY | G6: DAILY WORK - LAFC | H6: 0.33333333 | I6: BC | J6: STAFFING COORDINATOR | K6: FASTCO04 | L6: FCADM | M6: BSADM | N6: 45993 | O6: Tuesday | P6: No | Q6: 0.26974537 | R6: 0.6291088 | S6: 25.75 | T6: H | U6: FA0065 | V6: 8.12 | W6: 8 | X6: 0.12 | AH6: 206 | AI6: 4.64 | AP6: 210.64 | AR6: 0.26974537 | AS6: 0.6291088 | AT6: 0.26974537 | AV6: FCADM - LAFC - ADMIN | AY6: 0.5 | AZ6: O-11:12:26 / I-12:09:08 | BA6: 12/03/2025 - PALCALA | BD6: FASTCO | BE6: STAFFING COORDINATOR | BF6: FIRST MEAL MANUALLY RECORDED | BG6: 0 | BH6: 0 | BJ6: 0
A7: FCADM | B7: FCADM | C7: 100019803 | D7: ROBERTS, PAMALA B | E7: PT | F7: FDAILY | G7: DAILY WORK - LAFC | H7: 0.33333333 | I7: BC | J7: STAFFING COORDINATOR | K7: FASTCO04 | L7: FCADM | M7: BSADM | N7: 45994 | O7: Wednesday | P7: No | Q7: 0.25965278 | R7: 0.60532407 | S7: 25.75 | T7: H | U7: FA0065 | V7: 7.8 | W7: 7.8 | AH7: 200.85 | AP7: 200.85 | AR7: 0.25965278 | AS7: 0.60532407 | AT7: 0.25965278 | AV7: FCADM - LAFC - ADMIN | AY7: 0.5 | AZ7: O-11:55:14 / I-12:25:37 | BA7: 12/08/2025 - PALCALA | BD7: FASTCO | BE7: STAFFING COORDINATOR | BG7: 0 | BH7: 0 | BJ7: 0
A8: FCADM | B8: FCADM | C8: 100019803 | D8: ROBERTS, PAMALA B | E8: PT | F8: FDAILY | G8: DAILY WORK - LAFC | H8: 0.33333333 | I8: BC | J8: STAFFING COORDINATOR | K8: FASTCO04 | L8: FCADM | M8: BSADM | N8: 45995 | O8: Thursday | P8: No | Q8: 0.26013889 | R8: 0.59525463 | S8: 25.75 | T8: H | U8: FA0065 | V8: 7.31 | W8: 7.31 | AH8: 188.23 | AP8: 188.23 | AR8: 0.26013889 | AS8: 0.59525463 | AT8: 0.26013889 | AV8: FCADM - LAFC - ADMIN | AY8: 0.73 | AZ8: O-10:43:10 / I-11:27:13 | BA8: 12/08/2025 - PALCALA | BD8: FASTCO | BE8: STAFFING COORDINATOR | BG8: 0 | BH8: 0 | BJ8: 0
A9: FCADM | B9: FCADM | C9: 100019803 | D9: ROBERTS, PAMALA B | E9: PT | F9: FDAILY | G9: DAILY WORK - LAFC | H9: 0.33333333 | I9: BC | J9: STAFFING COORDINATOR | K9: FASTCO04 | L9: FCADM | M9: BSADM | N9: 46000 | O9: Tuesday | P9: No | Q9: 0.28402778 | R9: 0.63136574 | S9: 25.75 | T9: H | U9: FA0065 | V9: 7.84 | W9: 7.84 | AH9: 201.88 | AP9: 201.88 | AR9: 0.28402778 | AS9: 0.63136574 | AT9: 0.28402778 | AV9: FCADM - LAFC - ADMIN | AY9: 0.5 | AZ9: O-12:33:55 / I-13:07:36 | BA9: 12/10/2025 - PALCALA | BD9: FASTCO | BE9: STAFFING COORDINATOR | BG9: 0 | BH9: 0 | BJ9: 0
A10: FCADM | B10: FCADM | C10: 100019803 | D10: ROBERTS, PAMALA B | E10: PT | F10: FDAILY | G10: DAILY WORK - LAFC | H10: 0.33333333 | I10: BC | J10: STAFFING COORDINATOR | K10: FASTCO04 | L10: FCADM | M10: BSADM | N10: 46001 | O10: Wednesday | P10: No | Q10: 0.26954861 | R10: 0.65673611 | S10: 25.75 | T10: H | U10: FA0065 | V10: 8.66 | W10: 8 | X10: 0.66 | AH10: 206 | AI10: 25.49 | AP10: 231.49 | AR10: 0.26954861 | AS10: 0.65673611 | AT10: 0.26954861 | AV10: FCADM - LAFC - ADMIN | AY10: 0.63 | AZ10: O-11:40:03 / I-12:17:48 | BA10: 12/12/2025 - PALCALA | BD10: FASTCO | BE10: STAFFING COORDINATOR | BG10: 0 | BH10: 0 | BJ10: 0
A11: FCADM | B11: FCADM | C11: 100019803 | D11: ROBERTS, PAMALA B | E11: PT | F11: FDAILY | G11: DAILY WORK - LAFC | H11: 0.33333333 | I11: BC | J11: STAFFING COORDINATOR | K11: FASTCO04 | L11: FCADM | M11: BSADM | N11: 46002 | O11: Thursday | P11: No | Q11: 0.625 | R11: 0.99032407 | S11: 25.75 | T11: H | U11: FA0065 | V11: 8.27 | W11: 8 | X11: 0.27 | AH11: 206 | AI11: 10.43 | AP11: 216.43 | AR11: 0.63314815 | AS11: 0.99032407 | AT11: 0.63314815 | AV11: FCADM - LAFC - ADMIN | AY11: 0.5 | BA11: 12/12/2025 - PALCALA | BD11: FASTCO | BE11: STAFFING COORDINATOR | BF11: FIRST MEAL MANUALLY RECORDED IN PUNCH MANUALLY RECORDED | BG11: 0 | BH11: 0 | BJ11: 0
A12: FCADM | B12: FCADM | C12: 100019803 | D12: ROBERTS, PAMALA B | E12: PT | F12: FDAILY | G12: DAILY WORK - LAFC | H12: 0.33333333 | I12: BC | J12: STAFFING COORDINATOR | K12: FASTCO04 | L12: FCADM | M12: BSADM | N12: 46003 | O12: Friday | P12: No | Q12: 0.33333333 | R12: 0.375 | S12: 25.75 | T12: H | U12: FA0065 | V12: 1 | W12: 1 | AH12: 25.75 | AP12: 25.75 | AV12: FCADM - LAFC - ADMIN | BA12: 12/17/2025 - PALCALA | BD12: FASTCO | BE12: STAFFING COORDINATOR | BF12: PAY 1 HR CALL WITH HR AND YOLANDA | BG12: 0 | BH12: 0 | BJ12: 0
A13: FCADM | B13: FCADM | C13: 100019803 | D13: ROBERTS, PAMALA B | E13: PT | F13: FDAILY | G13: DAILY WORK - LAFC | H13: 0.33333333 | I13: BC | J13: STAFFING COORDINATOR | K13: FASTCO04 | L13: FCADM | M13: BSADM | N13: 46007 | O13: Tuesday | P13: No | Q13: 0.32627315 | R13: 0.66900463 | S13: 25.75 | T13: H | U13: FA0065 | V13: 7.73 | W13: 7.73 | AH13: 199.05 | AP13: 199.05 | AR13: 0.32627315 | AS13: 0.66900463 | AT13: 0.32627315 | AV13: FCADM - LAFC - ADMIN | AY13: 0.5 | AZ13: O-12:59:01 / I-13:52:27 | BA13: 12/17/2025 - PALCALA | BD13: FASTCO | BE13: STAFFING COORDINATOR | BF13: FIRST MEAL MANUALLY RECORDED | BG13: 0 | BH13: 0 | BJ13: 0
A14: FCADM | B14: FCADM | C14: 100019803 | D14: ROBERTS, PAMALA B | E14: PT | F14: FDAILY | G14: DAILY WORK - LAFC | H14: 0.33333333 | I14: BC | J14: STAFFING COORDINATOR | K14: FASTCO04 | L14: FCADM | M14: BSADM | N14: 46008 | O14: Wednesday | P14: No | Q14: 0.30666667 | R14: 0.67686343 | S14: 25.75 | T14: H | U14: FA0065 | V14: 8.38 | W14: 8 | X14: 0.38 | AH14: 206 | AI14: 14.68 | AP14: 220.68 | AR14: 0.30666667 | AS14: 0.67686343 | AT14: 0.30666667 | AV14: FCADM - LAFC - ADMIN | AY14: 0.5 | AZ14: O-13:26:36 / I-13:57:34 | BA14: 12/23/2025 - PALCALA | BD14: FASTCO | BE14: STAFFING COORDINATOR | BG14: 0 | BH14: 0 | BJ14: 0
A15: FCADM | B15: FCADM | C15: 100019803 | D15: ROBERTS, PAMALA B | E15: PT | F15: FDAILY | G15: DAILY WORK - LAFC | H15: 0.33333333 | I15: BC | J15: STAFFING COORDINATOR | K15: FASTCO04 | L15: FCADM | M15: BSADM | N15: 46009 | O15: Thursday | P15: No | Q15: 0.29944444 | R15: 0.65347222 | S15: 25.75 | T15: H | U15: FA0065 | V15: 8 | W15: 8 | AH15: 206 | AP15: 206 | AR15: 0.29944444 | AT15: 0.29944444 | AV15: FCADM - LAFC - ADMIN | AY15: 0.5 | AZ15: O-11:12:47 / I-12:14:58 | BA15: 12/23/2025 - PALCALA | BD15: FASTCO | BE15: STAFFING COORDINATOR | BF15: OUT PUNCH MANUALLY RECORDED | BG15: 0 | BH15: 0 | BJ15: 0
A16: FCBAR | B16: FCBAR | C16: 100029715 | D16: DIAZ, ANA I | E16: PT | F16: FDAILY | G16: DAILY WORK - LAFC | H16: 0.33333333 | I16: BC | J16: FIELD CLUB 100 BARTENDER | K16: FB100B08 | L16: FCBAR | M16: BSPB4 | N16: 46006 | O16: Monday | P16: No | Q16: 0.42539352 | R16: 0.65424769 | S16: 17.87 | T16: 1 | U16: FB0025 | V16: 5.49 | W16: 5.49 | AH16: 98.11 | AP16: 98.11 | AQ16: Yes | AR16: 0.42539352 | AS16: 0.65424769 | AT16: 0.41666667 | AU16: 0.625 | AV16: FCBAR - CLUBS | BA16: 12/16/2025 - PALCALA | BD16: FBBBTD | BE16: BARTENDER | BG16: 0 | BH16: 0 | BJ16: 0
A17: FCBAR | B17: FCBAR | C17: 100029715 | D17: DIAZ, ANA I | E17: PT | F17: FDAILY | G17: DAILY WORK - LAFC | H17: 0.33333333 | I17: BC | J17: FIELD CLUB 100 BARTENDER | K17: FB100B05 | L17: FCBAR | M17: BSPB4 | N17: 46008 | O17: Wednesday | P17: No | Q17: 0.42304398 | R17: 0.65652778 | S17: 17.87 | T17: 1 | U17: FB0025 | V17: 5.6 | W17: 5.6 | AH17: 100.07 | AP17: 100.07 | AR17: 0.42304398 | AS17: 0.65652778 | AT17: 0.41666667 | AU17: 0.58333333 | AV17: FCBAR - CLUBS | BA17: 12/18/2025 - PALCALA | BD17: FBBBTD | BE17: BARTENDER | BG17: 0 | BH17: 0 | BJ17: 0
A18: FCBAR | B18: FCBAR | C18: 100036211 | D18: CHAIREZ, RICARDO | E18: PT | F18: FDAILY | G18: DAILY WORK - LAFC | H18: 0.33333333 | I18: BC | J18: SUNSET TERRACE DECK BARTENDER | K18: FBSTDB01 | L18: FCBAR | M18: BSP7 | N18: 46000 | O18: Tuesday | P18: No | Q18: 0.38695602 | R18: 0.57457176 | S18: 18.25 | T18: 1 | U18: FB0035 | V18: 4 | W18: 4 | AH18: 73 | AP18: 73 | AQ18: Yes | AR18: 0.38695602 | AS18: 0.56971065 | AT18: 0.375 | AU18: 0.58333333 | AV18: FCBAR - CLUBS | AY18: 0.5 | AZ18: O-09:49:03 / I-10:20:22 | BA18: 12/10/2025 - PALCALA | BD18: FBBBTD | BE18: BARTENDER | BG18: 0 | BH18: 0 | BJ18: 0
A19: FCBAR | B19: FCBAR | C19: 100036211 | D19: CHAIREZ, RICARDO | E19: PT | F19: FDAILY | G19: DAILY WORK - LAFC | H19: 0.33333333 | I19: BC | J19: FIELD CLUB 100 BARTENDER | K19: FB100B07 | L19: FCBAR | M19: BSPB4 | N19: 46006 | O19: Monday | P19: No | Q19: 0.41969907 | R19: 0.6540162 | S19: 18.25 | T19: 1 | U19: FB0035 | V19: 5.62 | W19: 5.62 | AH19: 102.57 | AP19: 102.57 | AR19: 0.41969907 | AS19: 0.6540162 | AT19: 0.41666667 | AU19: 0.625 | AV19: FCBAR - CLUBS | BA19: 12/16/2025 - PALCALA | BD19: FBBBTD | BE19: BARTENDER | BG19: 0 | BH19: 0 | BJ19: 0
A20: FCBAR | B20: FCBAR | C20: 100036211 | D20: CHAIREZ, RICARDO | E20: PT | F20: FDAILY | G20: DAILY WORK - LAFC | H20: 0.33333333 | I20: BC | J20: FIELD CLUB 100 BARTENDER | K20: FB100B01 | L20: FCBAR | M20: BSPB4 | N20: 46007 | O20: Tuesday | P20: No | Q20: 0.42508102 | R20: 0.634375 | S20: 18.25 | T20: 1 | U20: FB0035 | V20: 5.02 | W20: 5.02 | AH20: 91.62 | AP20: 91.62 | AQ20: Yes | AR20: 0.42508102 | AS20: 0.634375 | AT20: 0.41666667 | AU20: 0.625 | AV20: FCBAR - CLUBS | BA20: 12/17/2025 - PALCALA | BD20: FBBBTD | BE20: BARTENDER | BG20: 0 | BH20: 0 | BJ20: 0
A21: FCBAR | B21: FCBAR | C21: 100036211 | D21: CHAIREZ, RICARDO | E21: PT | F21: FDAILY | G21: DAILY WORK - LAFC | H21: 0.33333333 | I21: BC | J21: FIELD CLUB 100 BARTENDER | K21: FB100B01 | L21: FCBAR | M21: BSPB4 | N21: 46008 | O21: Wednesday | P21: No | Q21: 0.44888889 | R21: 0.65820602 | S21: 18.25 | T21: 1 | U21: FB0035 | V21: 5.02 | W21: 5.02 | AH21: 91.62 | AP21: 91.62 | AR21: 0.44888889 | AS21: 0.65820602 | AT21: 0.44444444 | AU21: 0.58333333 | AV21: FCBAR - CLUBS | BA21: 12/18/2025 - PALCALA | BD21: FBBBTD | BE21: BARTENDER | BG21: 0 | BH21: 0 | BJ21: 0
A22: FCBAR | B22: FCBAR | C22: 100049378 | D22: MUNGUIA, JOSE | E22: PT | F22: FDAILY | G22: DAILY WORK - LAFC | H22: 0.33333333 | I22: BC | J22: FIELD CLUB 100 BARTENDER | K22: FB100B02 | L22: FCBAR | M22: BSPB4 | N22: 46008 | O22: Wednesday | P22: No | Q22: 0.42711806 | R22: 0.66439815 | S22: 17.87 | T22: 1 | U22: FB0025 | V22: 5.69 | W22: 5.69 | AH22: 101.68 | AP22: 101.68 | AQ22: Yes | AR22: 0.42711806 | AS22: 0.66439815 | AT22: 0.41666667 | AU22: 0.58333333 | AV22: FCBAR - CLUBS | BA22: 12/18/2025 - PALCALA | BD22: FBBBTD | BE22: BARTENDER | BG22: 0 | BH22: 0 | BJ22: 0
A23: FCBAR | B23: FCBAR | C23: 100064556 | D23: ARROYO, ISIAH | E23: PT | F23: FDAILY | G23: DAILY WORK - LAFC | H23: 0.33333333 | I23: BC | J23: DAILY WORK SUPERVISOR | K23: FADSUP03 | L23: FCBAR | M23: FCBARS | N23: 46007 | O23: Tuesday | P23: No | Q23: 0.43375 | R23: 0.63072917 | S23: 20 | T23: H | U23: FB0042 | V23: 4.73 | W23: 4.73 | AH23: 94.6 | AP23: 94.6 | AQ23: Yes | AR23: 0.43375 | AS23: 0.63072917 | AT23: 0.41666667 | AU23: 0.625 | AV23: FCBAR - CLUBS | BA23: 12/17/2025 - PALCALA | BD23: FBSUP | BE23: PREMIUM SUPERVISOR | BG23: 0 | BH23: 0 | BJ23: 0
A24: FCBAR | B24: FCBAR | C24: 100084246 | D24: GREEN, NATHANIEL | E24: PT | F24: FDAILY | G24: DAILY WORK - LAFC | H24: 0.33333333 | I24: BC | J24: DAILY WORK SUPERVISOR | K24: FADSUP01 | L24: FCBAR | M24: FCBARS | N24: 46006 | O24: Monday | P24: No | Q24: 0.46107639 | R24: 0.58068287 | S24: 20 | T24: H | U24: FB0042 | V24: 2.87 | W24: 2.87 | AH24: 57.4 | AP24: 57.4 | AR24: 0.46107639 | AS24: 0.58068287 | AT24: 0.45833333 | AU24: 0.625 | AV24: FCBAR - CLUBS | BA24: 12/16/2025 - PALCALA | BD24: FBSUP | BE24: PREMIUM SUPERVISOR | BG24: 0 | BH24: 0 | BJ24: 0
A25: FCBAR | B25: FCBAR | C25: 100084246 | D25: GREEN, NATHANIEL | E25: PT | F25: FDAILY | G25: DAILY WORK - LAFC | H25: 0.33333333 | I25: BC | J25: DAILY WORK SUPERVISOR | K25: FADSUP02 | L25: FCBAR | M25: FCBARS | N25: 46007 | O25: Tuesday | P25: No | Q25: 0.43056713 | R25: 0.63087963 | S25: 20 | T25: H | U25: FB0042 | V25: 4.81 | W25: 4.81 | AH25: 96.2 | AP25: 96.2 | AQ25: Yes | AR25: 0.43056713 | AS25: 0.63087963 | AT25: 0.41666667 | AU25: 0.625 | AV25: FCBAR - CLUBS | BA25: 12/17/2025 - PALCALA | BD25: FBSUP | BE25: PREMIUM SUPERVISOR | BG25: 0 | BH25: 0 | BJ25: 0
A26: FCBAR | B26: FCBAR | C26: 100087211 | D26: LEAL SILVA, MARCO A | E26: PT | F26: FDAILY | G26: DAILY WORK - LAFC | H26: 0.33333333 | I26: BC | J26: SUNSET TERRACE DECK BARBACK | K26: FBSTDK01 | L26: FCBAR | M26: BSP7 | N26: 46000 | O26: Tuesday | P26: No | Q26: 0.37774306 | R26: 0.56984954 | S26: 17.87 | T26: 1 | U26: FB0010 | V26: 4.61 | W26: 4.61 | AH26: 82.38 | AP26: 82.38 | AR26: 0.37774306 | AS26: 0.56984954 | AT26: 0.375 | AU26: 0.58333333 | AV26: FCBAR - CLUBS | BA26: 12/10/2025 - PALCALA | BD26: FBBBBK | BE26: BARBACK | BG26: 0 | BH26: 0 | BJ26: 0
A27: FCBAR | B27: FCBAR | C27: 100087211 | D27: LEAL SILVA, MARCO A | E27: PT | F27: FDAILY | G27: DAILY WORK - LAFC | H27: 0.33333333 | I27: BC | J27: FIELD CLUB 100 BARBACK | K27: FB100801 | L27: FCBAR | M27: BSPB4 | N27: 46006 | O27: Monday | P27: No | Q27: 0.41172454 | R27: 0.58533565 | S27: 17.87 | T27: 1 | U27: FB0010 | V27: 4.17 | W27: 4.17 | AH27: 74.52 | AP27: 74.52 | AR27: 0.41172454 | AS27: 0.58533565 | AT27: 0.41666667 | AU27: 0.625 | AV27: FCBAR - CLUBS | BA27: 12/16/2025 - PALCALA | BD27: FBBBBK | BE27: BARBACK | BG27: 0 | BH27: 0 | BJ27: 0
A28: FCBAR | B28: FCBAR | C28: 100087211 | D28: LEAL SILVA, MARCO A | E28: PT | F28: FDAILY | G28: DAILY WORK - LAFC | H28: 0.33333333 | I28: BC | J28: FIELD CLUB 100 BARBACK | K28: FB100801 | L28: FCBAR | M28: BSPB4 | N28: 46007 | O28: Tuesday | P28: No | Q28: 0.41186343 | R28: 0.63423611 | S28: 17.87 | T28: 1 | U28: FB0010 | V28: 5.34 | W28: 5.34 | AH28: 95.43 | AP28: 95.43 | AR28: 0.41186343 | AS28: 0.63423611 | AT28: 0.41666667 | AU28: 0.625 | AV28: FCBAR - CLUBS | BA28: 12/17/2025 - PALCALA | BD28: FBBBBK | BE28: BARBACK | BG28: 0 | BH28: 0 | BJ28: 0
A29: FCBAR | B29: FCBAR | C29: 100087211 | D29: LEAL SILVA, MARCO A | E29: PT | F29: FDAILY | G29: DAILY WORK - LAFC | H29: 0.33333333 | I29: BC | J29: FIELD CLUB 100 BARBACK | K29: FB100801 | L29: FCBAR | M29: BSPB4 | N29: 46008 | O29: Wednesday | P29: No | Q29: 0.4183912 | R29: 0.62896991 | S29: 17.87 | T29: 1 | U29: FB0010 | V29: 5.05 | W29: 5.05 | AH29: 90.24 | AP29: 90.24 | AR29: 0.4183912 | AS29: 0.62896991 | AT29: 0.41666667 | AU29: 0.58333333 | AV29: FCBAR - CLUBS | BA29: 12/18/2025 - PALCALA | BD29: FBBBBK | BE29: BARBACK | BG29: 0 | BH29: 0 | BJ29: 0
A30: FCCAT | B30: FCCAT | C30: 100002210 | D30: QUINTANAR, ROSEMARY | E30: PT | F30: F25C96 | G30: ABM HOLIDAY DINNER - CATERING | H30: 0.70833333 | I30: BS | J30: CATERING SERVER | K30: FCCAT74 | L30: FCCAT | M30: BSCAT | N30: 45994 | O30: Wednesday | P30: No | Q30: 0.57721065 | R30: 0.88244213 | S30: 22 | T30: 1 | U30: FC0030 | V30: 6.83 | W30: 6.83 | AH30: 150.26 | AP30: 150.26 | AR30: 0.57721065 | AS30: 0.88244213 | AT30: 0.58333333 | AU30: 0.85416667 | AV30: FCCAT - LAFC - CATERING | AY30: 0.5 | AZ30: O-15:03:51 / I-15:34:10 | BA30: 12/08/2025 - PALCALA | BD30: FCBSRV | BE30: CATERING SERVER | BG30: 0 | BH30: 0 | BJ30: 0
A31: FCCAT | B31: FCCAT | C31: 100002210 | D31: QUINTANAR, ROSEMARY | E31: PT | F31: F25C98 | G31: LA CLEANTECH INCUBATOR DAY 1 - CATERING | H31: 0.66666667 | I31: BS | J31: CATERING SERVER | K31: FCCAT24 | L31: FCCAT | M31: BSCAT | N31: 45999 | O31: Monday | P31: No | Q31: 0.49357639 | R31: 0.7741088 | S31: 22 | T31: 1 | U31: FC0030 | V31: 6.23 | W31: 6.23 | AH31: 137.06 | AP31: 137.06 | AR31: 0.49357639 | AS31: 0.7741088 | AT31: 0.5 | AU31: 0.85416667 | AV31: FCCAT - LAFC - CATERING | AY31: 0.5 | AZ31: O-14:10:36 / I-14:41:19 | BA31: 12/10/2025 - PALCALA | BD31: FCBSRV | BE31: CATERING SERVER | BG31: 0 | BH31: 0 | BJ31: 0
A32: FCCAT | B32: FCCAT | C32: 100002210 | D32: QUINTANAR, ROSEMARY | E32: PT | F32: F25C99 | G32: LA CLEANTECH INCUBATOR - DAY 2 - CATERING | H32: 0.375 | I32: BS | J32: CATERING SERVER | K32: FCCAT23 | L32: FCCAT | M32: BSCAT | N32: 46000 | O32: Tuesday | P32: No | Q32: 0.28822917 | R32: 0.69912037 | S32: 22 | T32: 1 | U32: FC0030 | V32: 9.86 | W32: 8 | X32: 1.86 | AH32: 176 | AI32: 61.38 | AP32: 237.38 | AR32: 0.28822917 | AS32: 0.69912037 | AT32: 0.29166667 | AU32: 0.625 | AV32: FCCAT - LAFC - CATERING | BA32: 12/10/2025 - PALCALA | BD32: FCBSRV | BE32: CATERING SERVER | BG32: 0 | BH32: 0 | BJ32: 0
A33: FCCAT | B33: FCCAT | C33: 100002210 | D33: QUINTANAR, ROSEMARY | E33: PT | F33: F25C00 | G33: BEECAN HOLIDAY PARTY - CATERING | H33: 0.79166667 | I33: BS | J33: CATERING SERVER | K33: FCCAT29 | L33: FCCAT | M33: BSCAT | N33: 46002 | O33: Thursday | P33: No | Q33: 0.71040509 | R33: 0.00040509259 | S33: 22 | T33: 1 | U33: FC0030 | V33: 7.96 | W33: 6.96 | AA33: 1 | AH33: 153.12 | AL33: 22 | AP33: 175.12 | AR33: 0.71040509 | AS33: 0.00040509259 | AT33: 0.70833333 | AU33: 1 | AV33: FCCAT - LAFC - CATERING | BA33: 12/16/2025 - PALCALA | BD33: FCBSRV | BE33: CATERING SERVER | BF33: MEAL PREMIUM | BG33: 0 | BH33: 0 | BJ33: 0
A34: FCCAT | B34: FCCAT | C34: 100002210 | D34: QUINTANAR, ROSEMARY | E34: PT | F34: F25C24 | G34: FISHER PHILLIPS HOLIDAY PARTY - CATERING | H34: 0.79166667 | I34: BS | J34: CATERING SERVER | K34: FCCAT22 | L34: FCCAT | M34: BSCAT | N34: 46003 | O34: Friday | P34: No | Q34: 0.68447917 | R34: 0.98534722 | S34: 22 | T34: 1 | U34: FC0030 | V34: 6.72 | W34: 6.72 | AH34: 147.84 | AP34: 147.84 | AR34: 0.68447917 | AS34: 0.98534722 | AT34: 0.6875 | AU34: 0.97916667 | AV34: FCCAT - LAFC - CATERING | AY34: 0.5 | AZ34: O-16:36:22 / I-17:06:40 | BA34: 12/16/2025 - PALCALA | BD34: FCBSRV | BE34: CATERING SERVER | BG34: 0 | BH34: 0 | BJ34: 0
A35: FCBAR | B35: FCCAT | C35: 100029715 | D35: DIAZ, ANA I | E35: PT | F35: F25C00 | G35: BEECAN HOLIDAY PARTY - CATERING | H35: 0.79166667 | I35: BS | J35: CATERING BARTENDER | K35: FCCATB11 | L35: FCCAT | M35: BSCAT | N35: 46002 | O35: Thursday | P35: No | Q35: 0.68310185 | R35: 0.99416667 | S35: 22 | T35: 1 | U35: FC020 | V35: 6.97 | W35: 6.97 | AE35: 175 | AH35: 153.34 | AP35: 328.34 | AR35: 0.68310185 | AS35: 0.99416667 | AT35: 0.6875 | AU35: 0.020833333 | AV35: FCBAR - | AY35: 0.5 | AZ35: O-16:23:56 / I-16:54:28 | BA35: 12/15/2025 - PALCALA | BD35: FCBART | BE35: CATERING BARTENDER | BG35: 0 | BH35: 0 | BJ35: 0
A36: FCBAR | B36: FCCAT | C36: 100029801 | D36: ALVARADO, LETICIA | E36: PT | F36: F25C00 | G36: BEECAN HOLIDAY PARTY - CATERING | H36: 0.79166667 | I36: BS | J36: CATERING BARTENDER | K36: FCCATB18 | L36: FCCAT | M36: BSCAT | N36: 46002 | O36: Thursday | P36: No | Q36: 0.68284722 | R36: 0.98175926 | S36: 22 | T36: 1 | U36: FC020 | V36: 6.67 | W36: 6.67 | AE36: 175 | AH36: 146.74 | AP36: 321.74 | AR36: 0.68284722 | AS36: 0.98175926 | AT36: 0.6875 | AU36: 1 | AV36: FCBAR - | AY36: 0.5 | BA36: 12/15/2025 - PALCALA | BD36: FCBART | BE36: CATERING BARTENDER | BF36: FIRST MEAL MANUALLY RECORDED | BG36: 0 | BH36: 0 | BJ36: 0
A37: FCCAT | B37: FCCAT | C37: 100030153 | D37: SOSA, VALERIA R | E37: PT | F37: FDAILY | G37: DAILY WORK - LAFC | H37: 0.33333333 | I37: BC | J37: CATERING SERVER | K37: FCCAT21 | L37: FCCAT | M37: BSCAT | N37: 45992 | O37: Monday | P37: No | Q37: 0.41350694 | R37: 0.65731481 | S37: 22 | T37: 1 | U37: FC0030 | V37: 5.85 | W37: 5.85 | AH37: 128.7 | AP37: 128.7 | AR37: 0.41350694 | AS37: 0.65731481 | AT37: 0.41666667 | AU37: 0.66666667 | AV37: FCCAT - LAFC - CATERING | BA37: 12/02/2025 - PALCALA | BD37: FCBSRV | BE37: CATERING SERVER | BG37: 0 | BH37: 0 | BJ37: 0
A38: FCCAT | B38: FCCAT | C38: 100030153 | D38: SOSA, VALERIA R | E38: PT | F38: F25C95 | G38: GLORIA TREVI PRESS EVENT - CATERING | H38: 0.66666667 | I38: BS | J38: CATERING SERVER | K38: FCCAT22 | L38: FCCAT | M38: BSCAT | N38: 45993 | O38: Tuesday | P38: No | Q38: 0.28736111 | R38: 0.60819444 | S38: 22 | T38: 1 | U38: FC0030 | V38: 7.11 | W38: 7.11 | AH38: 156.42 | AP38: 156.42 | AR38: 0.28736111 | AS38: 0.60819444 | AT38: 0.29166667 | AU38: 0.625 | AV38: FCCAT - LAFC - CATERING | AY38: 0.59 | AZ38: O-08:43:29 / I-09:18:48 | BA38: 12/03/2025 - PALCALA | BD38: FCBSRV | BE38: CATERING SERVER | BG38: 0 | BH38: 0 | BJ38: 0
A39: FCCAT | B39: FCCAT | C39: 100030153 | D39: SOSA, VALERIA R | E39: PT | F39: F25C96 | G39: ABM HOLIDAY DINNER - CATERING | H39: 0.70833333 | I39: BS | J39: CATERING SERVER | K39: FCCAT68 | L39: FCCAT | M39: BSCAT | N39: 45994 | O39: Wednesday | P39: No | Q39: 0.57638889 | R39: 0.88194444 | S39: 22 | T39: 1 | U39: FC0030 | V39: 6.83 | W39: 6.83 | AH39: 150.26 | AP39: 150.26 | AT39: 0.58333333 | AU39: 0.875 | AV39: FCCAT - LAFC - CATERING | AY39: 0.5 | BA39: 12/10/2025 - PALCALA | BD39: FCBSRV | BE39: CATERING SERVER | BF39: IN AND OUT PUNCH/FIRST MEAL MANUALLY RECORDED | BG39: 0 | BH39: 0 | BJ39: 0
A40: FCCAT | B40: FCCAT | C40: 100030153 | D40: SOSA, VALERIA R | E40: PT | F40: F25C97 | G40: FINNISH MOBILITY SHOWCASE - CATERING | H40: 0.70833333 | I40: BS | J40: CATERING SERVER | K40: FCCAT23 | L40: FCCAT | M40: BSCAT | N40: 45995 | O40: Thursday | P40: No | Q40: 0.58825231 | R40: 0.8437963 | S40: 22 | T40: 1 | U40: FC0030 | V40: 5.63 | W40: 5.63 | AH40: 123.86 | AP40: 123.86 | AR40: 0.58825231 | AS40: 0.8437963 | AT40: 0.58333333 | AU40: 0.85416667 | AV40: FCCAT - LAFC - CATERING | AY40: 0.5 | AZ40: O-15:11:43 / I-15:42:39 | BA40: 12/08/2025 - PALCALA | BD40: FCBSRV | BE40: CATERING SERVER | BG40: 0 | BH40: 0 | BJ40: 0
A41: FCCAT | B41: FCCAT | C41: 100030153 | D41: SOSA, VALERIA R | E41: PT | F41: FDAILY | G41: DAILY WORK - LAFC | H41: 0.33333333 | I41: BC | J41: CATERING SERVER | K41: FCCAT21 | L41: FCCAT | M41: BSCAT | N41: 45998 | O41: Sunday | P41: Yes | Q41: 0.3721875 | R41: 0.61778935 | S41: 22 | T41: 1 | U41: FC0030 | V41: 5.89 | W41: 5.89 | AH41: 129.58 | AP41: 129.58 | AR41: 0.3721875 | AS41: 0.61778935 | AT41: 0.375 | AU41: 0.625 | AV41: FCCAT - LAFC - CATERING | BA41: 12/08/2025 - PALCALA | BD41: FCBSRV | BE41: CATERING SERVER | BG41: 0 | BH41: 0 | BJ41: 0
...

Sheet term
A1: 100047412 | B1: BEBO, STEPHANIE | C1: Active | D1: Server, Catering | E1: 615-28-1335
A2: 100087214 | B2: BESSER III, FRANK L. | C2: Active | D2: Club Attendant | E2: 176-76-8381
A3: 100084264 | B3: Castillo, Christian | C3: Active | D3: Barback, Premium | E3: 606-17-2939
A4: 100074398 | B4: COCOMA, Jayde C. | C4: Active | D4: Warehouse Associate | E4: 578-39-0167
A5: 100084247 | B5: De La Rosa, Gesel | C5: Active | D5: Cashier, Concessions | E5: 626-25-3481
A6: 100087233 | B6: DIXON, KAMESHA S. | C6: Active | D6: Dishwasher | E6: 550-79-8394
A7: 100087231 | B7: Dixon, Tamesha F. | C7: Active | D7: Dishwasher | E7: 550-79-6307
A8: 100054473 | B8: JOHNSON, ALAYAH | C8: Active | D8: Concessions Stand Lead | E8: 626-41-7445
A9: 100054474 | B9: JONES, ERICK | C9: Active | D9: Club Attendant | E9: 604-21-5499
A10: 100062557 | B10: Jonewell, James | C10: Active | D10: Runner, Suites | E10: 104-66-5573
A11: 100074375 | B11: LOPEZ, ESMERALDA | C11: Active | D11: Runner, Suites | E11: 539-25-3879
A12: 100059517 | B12: MAK, Samatha | C12: Active | D12: Bartender, Premium | E12: 462-53-2217
... A32: 100048023 | B32: MENDEZ, BRIAN | C32: Active | D32: Cashier, Concessions | E32: 611-29-3237
A33: 100089106 | B33: Musa, Yahmani | C33: Active | D33: Club Attendant | E33: 603-23-0185
A34: 100060728 | B34: NEGRETE, JAVIER | C34: Active | D34: Dishwasher | E34: 624-58-0770
A35: 100087215 | B35: ORTIZ, VANESSA | C35: Active | D35: Concessions Stand Lead | E35: 555-91-0498
A36: 100087282 | B36: ROYAL, TONIA | C36: Active | D36: Concessions Stand Lead | E36: 458-29-4960
A37: 100030337 | B37: Sanchez, Marina | C37: Active | D37: Server, Catering | E37: 560-45-7252
A38: 100049325 | B38: SERVELLON Jr., ISAI | C38: Active | D38: Concessions Stand Lead | E38: 613-23-7693
A39: 100073366 | B39: Gonzalez Rosas, Abelardo | C39: Active | D39: Cook 3 | E39: 602-33-7921
A40: 100073274 | B40: AMEZOLA, FRED | C40: Active | D40: Cook 3 | E40: 547-77-1250
A41: 100036391 | B41: Sepulveda de Rodarte, Carmen | C41: Active | D41: Cook 2 | E41: 606-53-4186
A42: 100093390 | B42: Cooper, Cornell | C42: Active | D42: Concessions Stand Lead | E42: 554-57-2577
A43: 100029832 | B43: Peralta, Mayra L. | C43: Active | D43: Cashier, Concessions | E43: 605-86-7051
A44: 100053192 | B44: PEREZ, NANCY | C44: Active | D44: Cashier, Concessions | E44: 625-23-0781
A45: 100077499 | B45: MACIAS BARJAS, MIGUEL | C45: Active | D45: Cashier, Concessions | E45: 615-45-4078
A46: 100087286 | B46: Cruz, Juilan | C46: Active | D46: Concession Stand Worker | E46: 680-64-4979
A47: 100093407 | B47: Davis, Dimmery | C47: Active | D47: Cashier, Concessions | E47: 620-53-4186
A48: 100067131 | B48: Zechar, Lanny | C48: Active | D48: Lead Bartender, Concess | E48: 562-19-9743
A49: 100077488 | B49: ZARATE, DAVID A. | C49: Active | D49: Cashier, Concessions | E49: 610-51-7839
A50: 100087276 | B50: ZARAGOZA, MARTHA | C50: Active | D50: Club Attendant | E50: 609-50-6974
A51: 100087255 | B51: Wright, Bree | C51: Active | D51: Cook 3 | E51: 626-84-4281
A52: 100077562 | B52: ABDULLAH-LEE, NOAH H. | C52: Active | D52: Concession Stand Worker | E52: 614-39-2240
A53: 100077524 | B53: AGUIRRE, ALICE | C53: Active | D53: Cashier, Concessions | E53: 611-49-7156
A54: 100077561 | B54: ALLEN, ANIYA | C54: Active | D54: Cashier, Concessions | E54: 615-31-0176
A55: 100082246 | B55: Allison, Kameron | C55: Active | D55: Concession Stand Worker | E55: 323-02-9689
A56: 100082258 | B56: Amaya, Alma | C56: Active | D56: Concession Stand Worker | E56: 618-50-8242
A57: 100087246 | B57: ANGEL, MELVIN | C57: Active | D57: Cook 3 | E57: 626-29-6117
A58: 100077548 | B58: SANCHEZ II, MARCIA A. | C58: Active | D58: Cashier, Concessions | E58: 756-79-5916
A59: 100087261 | B59: Sanchez, Jesus | C59: Active | D59: Concession Stand Worker | E59: 609-60-1320
...

Sheet 11.27.22

Sheet 12.04.22

Sheet 12.08.22

Sheet 12.11.22

Sheet 12.17.22

Sheet 12.18.22

Sheet 12.25.22

Sheet Terminated
A1: Company | B1: Employee Name (Last Suffix, First MI) | C1: Employee Number | D1: Employment Status | E1: Status As Of | F1: Employee Email | G1: Last Hire | H1: Job Start | I1: Location | J1: Job Code | K1: Job

Sheet New Hire
A1: Employee Name (Last Suffix, First MI) | B1: Employee Number | C1: Birth Date | D1: Start Date (History) | E1: Job | F1: Address Line 1 + Address Line 2 | G1: City, State Zip Code (Formatted) | H1: Gender | I1: SSN (Formatted)
